Workbook

Sheet Datos
A1: Fecha | B1: Tipo de Datos | C1: Tamaño de DB (GB) | D1: Tiempo de Procesamiento (Horas) | E1: Calidad de Datos | F1: Experiencia del Equipo (Años) | G1: Nivel de Integración
A2: 45112 | B2: No Estructurados | C2: 18.248357 | D2: 12.650402 | E2: 3 | F2: 11 | G2: 2
A3: 45172 | B3: No Estructurados | C3: 9.9308678 | D3: 7.846512 | E3: 4 | F3: 5 | G3: 4
A4: 45051 | B4: No Estructurados | C4: 16.323844 | D4: 18.293437 | E4: 4 | F4: 20 | G4: 5
A5: 45194 | B5: Estructurados | C5: 19.761515 | D5: 16.354214 | E5: 5 | F5: 11 | G5: 1
A6: 45057 | B6: Estructurados | C6: 10.882923 | D6: 12.844001 | E6: 5 | F6: 10 | G6: 5
A7: 45163 | B7: No Estructurados | C7: 12.882932 | D7: 12.094613 | E7: 3 | F7: 8 | G7: 2
A8: 44944 | B8: Estructurados | C8: 14.789606 | D8: 11.389639 | E8: 2 | F8: 6 | G8: 5
A9: 44966 | B9: No Estructurados | C9: 16.383717 | D9: 9.9412842 | E9: 5 | F9: 6 | G9: 1
A10: 44947 | B10: Estructurados | C10: 11.765263 | D10: 17.777648 | E10: 4 | F10: 8 | G10: 2
A11: 45151 | B11: No Estructurados | C11: 14.27128 | D11: 17.904703 | E11: 3 | F11: 15 | G11: 5
A12: 45281 | B12: No Estructurados | C12: 10.768291 | D12: 11.197855 | E12: 5 | F12: 14 | G12: 4
A13: 45208 | B13: Estructurados | C13: 15.767135 | D13: 13.224495 | E13: 4 | F13: 11 | G13: 2
... A401: 45230 | B401: Estructurados | C401: 20.618908 | D401: 11.988908 | E401: 5 | F401: 8 | G401: 1

Sheet 1. Descriptivo
A1: Meta 1 — Análisis Descriptivo de Variables Clave
A4: Estadístico | B4: Tamaño DB (GB) | C4: Tiempo Proc. (Horas) | D4: Calidad de Datos | E4: Experiencia (Años) | F4: Nivel Integración
A5: N (conteo) | B5: =COUNT(Datos!C2:C401) -> 400 | C5: =COUNT(Datos!D2:D401) -> 400 | D5: =COUNT(Datos!E2:E401) -> 400 | E5: =COUNT(Datos!F2:F401) -> 400 | F5: =COUNT(Datos!G2:G401) -> 400
A6: Media | B6: =AVERAGE(Datos!C2:C401) -> 14.861274 | C6: =AVERAGE(Datos!D2:D401) -> 13.611924 | D6: =AVERAGE(Datos!E2:E401) -> 3.88 | E6: =AVERAGE(Datos!F2:F401) -> 10.51 | F6: =AVERAGE(Datos!G2:G401) -> 2.935
A7: Mediana | B7: =MEDIAN(Datos!C2:C401) -> 14.863797 | C7: =MEDIAN(Datos!D2:D401) -> 13.678112 | D7: =MEDIAN(Datos!E2:E401) -> 4 | E7: =MEDIAN(Datos!F2:F401) -> 10 | F7: =MEDIAN(Datos!G2:G401) -> 3
A8: Moda | B8: =IFERROR(_xlfn.MODE.SNGL(Datos!C2:C401),"sin moda") -> sin moda | C8: =IFERROR(_xlfn.MODE.SNGL(Datos!D2:D401),"sin moda") -> sin moda | D8: =IFERROR(_xlfn.MODE.SNGL(Datos!E2:E401),"sin moda") -> 4 | E8: =IFERROR(_xlfn.MODE.SNGL(Datos!F2:F401),"sin moda") -> 8 | F8: =IFERROR(_xlfn.MODE.SNGL(Datos!G2:G401),"sin moda") -> 1
A9: Mínimo | B9: =MIN(Datos!C2:C401) -> 3.0406144 | C9: =MIN(Datos!D2:D401) -> 3.0052546 | D9: =MIN(Datos!E2:E401) -> 2 | E9: =MIN(Datos!F2:F401) -> 1 | F9: =MIN(Datos!G2:G401) -> 1
A10: Máximo | B10: =MAX(Datos!C2:C401) -> 26.094901 | C10: =MAX(Datos!D2:D401) -> 22.449473 | D10: =MAX(Datos!E2:E401) -> 5 | E10: =MAX(Datos!F2:F401) -> 20 | F10: =MAX(Datos!G2:G401) -> 5
A11: Rango | B11: =MAX(Datos!C2:C401)-MIN(Datos!C2:C401) -> 23.054287 | C11: =MAX(Datos!D2:D401)-MIN(Datos!D2:D401) -> 19.444219 | D11: =MAX(Datos!E2:E401)-MIN(Datos!E2:E401) -> 3 | E11: =MAX(Datos!F2:F401)-MIN(Datos!F2:F401) -> 19 | F11: =MAX(Datos!G2:G401)-MIN(Datos!G2:G401) -> 4
A12: Varianza (muestral) | B12: =_xlfn.VAR.S(Datos!C2:C401) -> 17.247045 | C12: =_xlfn.VAR.S(Datos!D2:D401) -> 9.7187274 | D12: =_xlfn.VAR.S(Datos!E2:E401) -> 0.87779449 | E12: =_xlfn.VAR.S(Datos!F2:F401) -> 34.566316 | F12: =_xlfn.VAR.S(Datos!G2:G401) -> 2.1060401
A13: Desv. estándar (muestral) | B13: =_xlfn.STDEV.S(Datos!C2:C401) -> 4.1529562 | C13: =_xlfn.STDEV.S(Datos!D2:D401) -> 3.1174874 | D13: =_xlfn.STDEV.S(Datos!E2:E401) -> 0.93690687 | E13: =_xlfn.STDEV.S(Datos!F2:F401) -> 5.8793125 | F13: =_xlfn.STDEV.S(Datos!G2:G401) -> 1.4512202
A14: Coef. variación | B14: =_xlfn.STDEV.S(Datos!C2:C401)/AVERAGE(Datos!C2:C401) -> 0.27944819 | C14: =_xlfn.STDEV.S(Datos!D2:D401)/AVERAGE(Datos!D2:D401) -> 0.22902621 | D14: =_xlfn.STDEV.S(Datos!E2:E401)/AVERAGE(Datos!E2:E401) -> 0.24147084 | E14: =_xlfn.STDEV.S(Datos!F2:F401)/AVERAGE(Datos!F2:F401) -> 0.55940176 | F14: =_xlfn.STDEV.S(Datos!G2:G401)/AVERAGE(Datos!G2:G401) -> 0.49445322
A15: Cuartil 1 (Q1) | B15: =_xlfn.QUARTILE.INC(Datos!C2:C401,1) -> 12.256266 | C15: =_xlfn.QUARTILE.INC(Datos!D2:D401,1) -> 11.5587 | D15: =_xlfn.QUARTILE.INC(Datos!E2:E401,1) -> 3 | E15: =_xlfn.QUARTILE.INC(Datos!F2:F401,1) -> 6 | F15: =_xlfn.QUARTILE.INC(Datos!G2:G401,1) -> 2
A16: Cuartil 3 (Q3) | B16: =_xlfn.QUARTILE.INC(Datos!C2:C401,3) -> 17.485185 | C16: =_xlfn.QUARTILE.INC(Datos!D2:D401,3) -> 15.754484 | D16: =_xlfn.QUARTILE.INC(Datos!E2:E401,3) -> 5 | E16: =_xlfn.QUARTILE.INC(Datos!F2:F401,3) -> 16 | F16: =_xlfn.QUARTILE.INC(Datos!G2:G401,3) -> 4
A17: Rango intercuartílico (IQR) | B17: =_xlfn.QUARTILE.INC(Datos!C2:C401,3)-_xlfn.QUARTILE.INC(Datos!C2:C401,1) -> 5.2289187 | C17: =_xlfn.QUARTILE.INC(Datos!D2:D401,3)-_xlfn.QUARTILE.INC(Datos!D2:D401,1) -> 4.195784 | D17: =_xlfn.QUARTILE.INC(Datos!E2:E401,3)-_xlfn.QUARTILE.INC(Datos!E2:E401,1) -> 2 | E17: =_xlfn.QUARTILE.INC(Datos!F2:F401,3)-_xlfn.QUARTILE.INC(Datos!F2:F401,1) -> 10 | F17: =_xlfn.QUARTILE.INC(Datos!G2:G401,3)-_xlfn.QUARTILE.INC(Datos!G2:G401,1) -> 2
A18: Sesgo (asimetría) | B18: =SKEW(Datos!C2:C401) -> 0.039100099 | C18: =SKEW(Datos!D2:D401) -> -0.18313367 | D18: =SKEW(Datos!E2:E401) -> -0.34677446 | E18: =SKEW(Datos!F2:F401) -> 0.028572003 | F18: =SKEW(Datos!G2:G401) -> 0.1038179
A19: Curtosis (exceso) | B19: =KURT(Datos!C2:C401) -> -0.16770026 | C19: =KURT(Datos!D2:D401) -> 0.1600098 | D19: =KURT(Datos!E2:E401) -> -0.85888112 | E19: =KURT(Datos!F2:F401) -> -1.2131086 | F19: =KURT(Datos!G2:G401) -> -1.335417
A21: Tabla de Frecuencias — Tiempo de Procesamiento
A22: Clase (Horas) | B22: Lím. Inf. | C22: Lím. Sup. | D22: Marca de clase | E22: Frecuencia | F22: Frec. Acumulada
A23: [3, 5) | B23: 3 | C23: 5 | D23: =(B23+C23)/2 -> 4 | E23: =COUNTIFS(Datos!$D$2:$D$401,">="&B23,Datos!$D$2:$D$401,"<"&C23) -> 3 | F23: =E23 -> 3
A24: [5, 7) | B24: 5 | C24: 7 | D24: =(B24+C24)/2 -> 6 | E24: =COUNTIFS(Datos!$D$2:$D$401,">="&B24,Datos!$D$2:$D$401,"<"&C24) -> 1 | F24: =E23+E24 -> 4
A25: [7, 9) | B25: 7 | C25: 9 | D25: =(B25+C25)/2 -> 8 | E25: =COUNTIFS(Datos!$D$2:$D$401,">="&B25,Datos!$D$2:$D$401,"<"&C25) -> 25 | F25: =F24+E25 -> 29
A26: [9, 11) | B26: 9 | C26: 11 | D26: =(B26+C26)/2 -> 10 | E26: =COUNTIFS(Datos!$D$2:$D$401,">="&B26,Datos!$D$2:$D$401,"<"&C26) -> 46 | F26: =F25+E26 -> 75
A27: [11, 13) | B27: 11 | C27: 13 | D27: =(B27+C27)/2 -> 12 | E27: =COUNTIFS(Datos!$D$2:$D$401,">="&B27,Datos!$D$2:$D$401,"<"&C27) -> 92 | F27: =F26+E27 -> 167
A28: [13, 15) | B28: 13 | C28: 15 | D28: =(B28+C28)/2 -> 14 | E28: =COUNTIFS(Datos!$D$2:$D$401,">="&B28,Datos!$D$2:$D$401,"<"&C28) -> 98 | F28: =F27+E28 -> 265
A29: [15, 17) | B29: 15 | C29: 17 | D29: =(B29+C29)/2 -> 16 | E29: =COUNTIFS(Datos!$D$2:$D$401,">="&B29,Datos!$D$2:$D$401,"<"&C29) -> 76 | F29: =F28+E29 -> 341
A30: [17, 19) | B30: 17 | C30: 19 | D30: =(B30+C30)/2 -> 18 | E30: =COUNTIFS(Datos!$D$2:$D$401,">="&B30,Datos!$D$2:$D$401,"<"&C30) -> 48 | F30: =F29+E30 -> 389
A31: [19, 21) | B31: 19 | C31: 21 | D31: =(B31+C31)/2 -> 20 | E31: =COUNTIFS(Datos!$D$2:$D$401,">="&B31,Datos!$D$2:$D$401,"<"&C31) -> 8 | F31: =F30+E31 -> 397
A32: [21, 23) | B32: 21 | C32: 23 | D32: =(B32+C32)/2 -> 22 | E32: =COUNTIFS(Datos!$D$2:$D$401,">="&B32,Datos!$D$2:$D$401,"<"&C32) -> 3 | F32: =F31+E32 -> 400
A33: Total | E33: =SUM(E23:E32) -> 400

Sheet 2. Caja y Bigote
A1: Meta 2 — Diagrama de Caja y Bigote (Tiempo de Procesamiento)
A4: Estadístico | B4: Valor
A5: Mínimo | B5: =MIN(Datos!D2:D401) -> 3.0052546
A6: Cuartil 1 (Q1) | B6: =_xlfn.QUARTILE.INC(Datos!D2:D401,1) -> 11.5587
A7: Mediana (Q2) | B7: =MEDIAN(Datos!D2:D401) -> 13.678112
A8: Cuartil 3 (Q3) | B8: =_xlfn.QUARTILE.INC(Datos!D2:D401,3) -> 15.754484
A9: Máximo | B9: =MAX(Datos!D2:D401) -> 22.449473
A10: IQR = Q3 - Q1 | B10: =_xlfn.QUARTILE.INC(Datos!D2:D401,3)-_xlfn.QUARTILE.INC(Datos!D2:D401,1) -> 4.195784
A11: Límite inferior = Q1 - 1.5·IQR | B11: =_xlfn.QUARTILE.INC(Datos!D2:D401,1)-1.5*(_xlfn.QUARTILE.INC(Datos!D2:D401,3)-_xlfn.QUARTILE.INC(Datos!D2:D401,1)) -> 5.265024
A12: Límite superior = Q3 + 1.5·IQR | B12: =_xlfn.QUARTILE.INC(Datos!D2:D401,3)+1.5*(_xlfn.QUARTILE.INC(Datos!D2:D401,3)-_xlfn.QUARTILE.INC(Datos!D2:D401,1)) -> 22.04816
A14: Atípicos por debajo (< Lím. inf.) | B14: =COUNTIF(Datos!D2:D401,"<"&B11) -> 3
A15: Atípicos por encima (> Lím. sup.) | B15: =COUNTIF(Datos!D2:D401,">"&B12) -> 2
A16: Total de valores atípicos | B16: =B14+B15 -> 5
A17: % de atípicos sobre el total | B17: =(B14+B15)/COUNT(Datos!D2:D401) -> 0.0125
A20: Datos para diagrama de caja y bigote
A21: Categoría | B21: Base (Mín) | C21: Q1-Mín | D21: Mediana-Q1 | E21: Q3-Mediana | F21: Máx-Q3
A22: Tiempo (h) | B22: =B5 -> 3.0052546 | C22: =B6-B5 -> 8.5534454 | D22: =B7-B6 -> 2.1194118 | E22: =B8-B7 -> 2.0763722 | F22: =B9-B8 -> 6.6949895

Sheet 3. Estándar Calidad
A1: Meta 3 — Cumplimiento del Estándar de Calidad
A4: Nivel de Calidad | B4: Frecuencia | C4: Frec. Relativa | D4: Frec. Acumulada
A5: 1 | B5: =COUNTIF(Datos!$E$2:$E$401,1) -> 0 | C5: =B5/COUNT(Datos!$E$2:$E$401) -> 0 | D5: =C5 -> 0
A6: 2 | B6: =COUNTIF(Datos!$E$2:$E$401,2) -> 32 | C6: =B6/COUNT(Datos!$E$2:$E$401) -> 0.08 | D6: =D5+C6 -> 0.08
A7: 3 | B7: =COUNTIF(Datos!$E$2:$E$401,3) -> 106 | C7: =B7/COUNT(Datos!$E$2:$E$401) -> 0.265 | D7: =D6+C7 -> 0.345
A8: 4 | B8: =COUNTIF(Datos!$E$2:$E$401,4) -> 140 | C8: =B8/COUNT(Datos!$E$2:$E$401) -> 0.35 | D8: =D7+C8 -> 0.695
A9: 5 | B9: =COUNTIF(Datos!$E$2:$E$401,5) -> 122 | C9: =B9/COUNT(Datos!$E$2:$E$401) -> 0.305 | D9: =D8+C9 -> 1
A10: Total | B10: =SUM(B5:B9) -> 400 | C10: =SUM(C5:C9) -> 1
A12: Registros con Calidad ≥ 4 | B12: =COUNTIF(Datos!E2:E401,">=4") -> 262
A13: Total de registros | B13: =COUNT(Datos!E2:E401) -> 400
A14: Proporción con Calidad ≥ 4 | B14: =B12/B13 -> 0.655
A15: Estándar exigido | B15: 0.8
A16: ¿Cumple el estándar? | B16: =IF(B14>=B15,"SÍ CUMPLE","NO CUMPLE") -> NO CUMPLE

Sheet 4. Comparación Tipo
A1: Meta 4 — Tiempo de Procesamiento: Estructurados vs. No Estructurados
A4: Estadístico | B4: Estructurados | C4: No Estructurados
A5: N (conteo) | B5: =COUNTIF(Datos!B2:B401,"Estructurados") -> 202 | C5: =COUNTIF(Datos!B2:B401,"No Estructurados") -> 198
A6: Media | B6: =AVERAGEIF(Datos!B2:B401,"Estructurados",Datos!D2:D401) -> 13.672922 | C6: =AVERAGEIF(Datos!B2:B401,"No Estructurados",Datos!D2:D401) -> 13.549694
A7: Mediana | B7: {=MEDIAN(IF(Datos!B2:B401="Estructurados",Datos!D2:D401))} -> 13.91478 | C7: {=MEDIAN(IF(Datos!B2:B401="No Estructurados",Datos!D2:D401))} -> 13.505359
A8: Desv. estándar | B8: {=_xlfn.STDEV.S(IF(Datos!B2:B401="Estructurados",Datos!D2:D401))} -> 3.2823436 | C8: {=_xlfn.STDEV.S(IF(Datos!B2:B401="No Estructurados",Datos!D2:D401))} -> 2.9468422
A9: Mínimo | B9: =_xlfn.MINIFS(Datos!D2:D401,Datos!B2:B401,"Estructurados") -> 3.0052546 | C9: =_xlfn.MINIFS(Datos!D2:D401,Datos!B2:B401,"No Estructurados") -> 4.2387433
A10: Máximo | B10: =_xlfn.MAXIFS(Datos!D2:D401,Datos!B2:B401,"Estructurados") -> 22.449473 | C10: =_xlfn.MAXIFS(Datos!D2:D401,Datos!B2:B401,"No Estructurados") -> 19.867427
A12: Diferencia de medias (Estruct. - No Estruct.) | B12: =B6-C6 -> 0.12322729

Sheet 5. Regresión Simple
A1: Metas 5 — Regresión Lineal Simple
A4: Parámetro | B4: Valor
A5: Pendiente (b1) | B5: =SLOPE(Datos!D2:D401,Datos!C2:C401) -> 0.29134837
A6: Intercepto (b0) | B6: =INTERCEPT(Datos!D2:D401,Datos!C2:C401) -> 9.2821161
A7: Coef. correlación (r) | B7: =CORREL(Datos!C2:C401,Datos!D2:D401) -> 0.3881193
A8: Coef. determinación (R²) | B8: =RSQ(Datos!D2:D401,Datos!C2:C401) -> 0.15063659
A9: Error típico estimación | B9: =STEYX(Datos!D2:D401,Datos!C2:C401) -> 2.876712
A10: Covarianza muestral | B10: =_xlfn.COVARIANCE.S(Datos!C2:C401,Datos!D2:D401) -> 5.0248985
A11: Ecuación estimada | B11: =CONCATENATE("Tiempo = ",TEXT(B6,"0.000")," + ",TEXT(B5,"0.000")," · GB") -> Tiempo = 9.282 + 0.291 · GB
A12: Fuerza de correlación | B12: =IF(ABS(B7)<0.3,"Débil",IF(ABS(B7)<0.7,"Moderada","Fuerte")) -> Moderada

Sheet 6. Regresion Multiple
A1: X1 | B1: X2 | C1: X3 | D1: X4 | E1: X5 | F1: y | H1: PUNTO 6 — REGRESIÓN LINEAL MÚLTIPLE: PREDICCIÓN DEL TIEMPO DE PROCESAMIENTO
A2: Tamaño de DB (GB) | B2: Tipo de Datos: ESTRUCTURADOS=1, NO ESTRUCTURADOS=0 | C2: Calidad de Datos | D2: Experiencia del Equipo (Años) | E2: Nivel de Integración | F2: Tiempo de Procesamiento (Horas)
A3: 18.248357 | B3: =IF([2]Datos!B2="Estructurados",1,0) -> 0 | C3: 3 | D3: 11 | E3: 2 | F3: 12.650402 | H3: 6. Ecuación de regresión
A4: 9.9308678 | B4: =IF([2]Datos!B3="Estructurados",1,0) -> 0 | C4: 4 | D4: 5 | E4: 4 | F4: 7.846512 | H4: Y= 7.5865 +0.2730X1+0.1996X2-0.4443X3+0.2213X4+0.4306X5
A5: 16.323844 | B5: =IF([2]Datos!B4="Estructurados",1,0) -> 0 | C5: 4 | D5: 20 | E5: 5 | F5: 18.293437
A6: 19.761515 | B6: =IF([2]Datos!B5="Estructurados",1,0) -> 1 | C6: 5 | D6: 11 | E6: 1 | F6: 16.354214
A7: 10.882923 | B7: =IF([2]Datos!B6="Estructurados",1,0) -> 1 | C7: 5 | D7: 10 | E7: 5 | F7: 12.844001 | H7: Resumen
A8: 12.882932 | B8: =IF([2]Datos!B7="Estructurados",1,0) -> 0 | C8: 3 | D8: 8 | E8: 2 | F8: 12.094613
A9: 14.789606 | B9: =IF([2]Datos!B8="Estructurados",1,0) -> 1 | C9: 2 | D9: 6 | E9: 5 | F9: 11.389639 | H9: Estadísticas de la regresión
A10: 16.383717 | B10: =IF([2]Datos!B9="Estructurados",1,0) -> 0 | C10: 5 | D10: 6 | E10: 1 | F10: 9.9412842 | H10: Coeficiente de correlación múltiple | I10: 0.59392545
A11: 11.765263 | B11: =IF([2]Datos!B10="Estructurados",1,0) -> 1 | C11: 4 | D11: 8 | E11: 2 | F11: 17.777648 | H11: Coeficiente de determinación R^2 | I11: 0.35274744
A12: 14.27128 | B12: =IF([2]Datos!B11="Estructurados",1,0) -> 0 | C12: 3 | D12: 15 | E12: 5 | F12: 17.904703 | H12: R^2 ajustado | I12: 0.34453358
A13: 10.768291 | B13: =IF([2]Datos!B12="Estructurados",1,0) -> 0 | C13: 5 | D13: 14 | E13: 4 | F13: 11.197855 | H13: Error típico | I13: 2.5239452
A14: 15.767135 | B14: =IF([2]Datos!B13="Estructurados",1,0) -> 1 | C14: 4 | D14: 11 | E14: 2 | F14: 13.224495 | H14: Observaciones | I14: 400
A15: 16.120981 | B15: =IF([2]Datos!B14="Estructurados",1,0) -> 1 | C15: 5 | D15: 12 | E15: 2 | F15: 11.319783
A16: 12.04336 | B16: =IF([2]Datos!B15="Estructurados",1,0) -> 0 | C16: 4 | D16: 13 | E16: 4 | F16: 16.053875 | H16: ANÁLISIS DE VARIANZA
A17: 16.137541 | B17: =IF([2]Datos!B16="Estructurados",1,0) -> 0 | C17: 5 | D17: 8 | E17: 3 | F17: 14.691368 | I17: Grados de libertad | J17: Suma de cuadrados | K17: Promedio de los cuadrados | L17: F | M17: Valor crítico de F
A18: 9.7188562 | B18: =IF([2]Datos!B17="Estructurados",1,0) -> 1 | C18: 5 | D18: 18 | E18: 1 | F18: 14.585084 | H18: Regresión | I18: 5 | J18: 1367.8742 | K18: 273.57485 | L18: 42.945366 | M18: 2.6973374e-35
A19: 11.493584 | B19: =IF([2]Datos!B18="Estructurados",1,0) -> 1 | C19: 4 | D19: 1 | E19: 3 | F19: 9.6594152 | H19: Residuos | I19: 394 | J19: 2509.898 | K19: 6.3702995
A20: 13.157124 | B20: =IF([2]Datos!B19="Estructurados",1,0) -> 0 | C20: 5 | D20: 15 | E20: 5 | F20: 14.24281 | H20: Total | I20: 399 | J20: 3877.7722
A21: 14.545988 | B21: =IF([2]Datos!B20="Estructurados",1,0) -> 1 | C21: 5 | D21: 8 | E21: 4 | F21: 9.2541406
A22: 8.2938481 | B22: =IF([2]Datos!B21="Estructurados",1,0) -> 0 | C22: 5 | D22: 11 | E22: 3 | F22: 8.2039122 | I22: Coeficientes | J22: Error típico | K22: Estadístico t | L22: Probabilidad | M22: Inferior 95% | N22: Superior 95% | O22: Inferior 95.0% | P22: Superior 95.0%
A23: 6.7328244 | B23: =IF([2]Datos!B22="Estructurados",1,0) -> 0 | C23: 3 | D23: 12 | E23: 2 | F23: 14.952776 | H23: Intercepción | I23: 7.5865033 | J23: 0.82663113 | K23: 9.1776163 | L23: 2.5151436e-18 | M23: 5.9613439 | N23: 9.2116628 | O23: 5.9613439 | P23: 9.2116628
A24: 13.887112 | B24: =IF([2]Datos!B23="Estructurados",1,0) -> 0 | C24: 5 | D24: 12 | E24: 5 | F24: 12.452029 | H24: Tamaño de DB (GB) | I24: 0.27307507 | J24: 0.031174553 | K24: 8.7595504 | L24: 5.8763276e-17 | M24: 0.2117858 | N24: 0.33436434 | O24: 0.2117858 | P24: 0.33436434
A25: 19.033764 | B25: =IF([2]Datos!B24="Estructurados",1,0) -> 0 | C25: 5 | D25: 4 | E25: 5 | F25: 11.223453 | H25: Tipo de Datos: ESTRUCTURADOS=1, NO ESTRUCTURADOS=0 | I25: 0.19969178 | J25: 0.25341901 | K25: 0.78799053 | L25: 0.43117606 | M25: -0.2985308 | N25: 0.69791435 | O25: -0.2985308 | P25: 0.69791435
A26: 11.287626 | B26: =IF([2]Datos!B25="Estructurados",1,0) -> 1 | C26: 2 | D26: 16 | E26: 3 | F26: 15.359404 | H26: Calidad de Datos | I26: -0.44429575 | J26: 0.13812524 | K26: -3.2166152 | L26: 0.0014042784 | M26: -0.71585041 | N26: -0.17274109 | O26: -0.71585041 | P26: -0.17274109
A27: 9.7278086 | B27: =IF([2]Datos!B26="Estructurados",1,0) -> 1 | C27: 3 | D27: 4 | E27: 3 | F27: 13.388666 | H27: Experiencia del Equipo (Años) | I27: 0.22134912 | J27: 0.02192258 | K27: 10.096855 | L27: 1.8005453e-21 | M27: 0.17824926 | N27: 0.26444898 | O27: 0.17824926 | P27: 0.26444898
A28: 18.055461 | B28: =IF([2]Datos!B27="Estructurados",1,0) -> 1 | C28: 2 | D28: 5 | E28: 4 | F28: 12.905975 | H28: Nivel de Integración | I28: 0.43060349 | J28: 0.088491548 | K28: 4.8660409 | L28: 1.6496832e-06 | M28: 0.25662882 | N28: 0.60457816 | O28: 0.25662882 | P28: 0.60457816
A29: 16.424503 | B29: =IF([2]Datos!B28="Estructurados",1,0) -> 1 | C29: 4 | D29: 5 | E29: 1 | F29: 3.0225315
A30: 18.187849 | B30: =IF([2]Datos!B29="Estructurados",1,0) -> 1 | C30: 5 | D30: 8 | E30: 3 | F30: 11.704678 | H30: 6.Justificación de Variables
A31: 12.699681 | B31: =IF([2]Datos!B30="Estructurados",1,0) -> 1 | C31: 5 | D31: 10 | E31: 3 | F31: 16.054967 | H31: X1 | I31: Tamaño de DB (GB) | N31: A mayor tamaño, normalmente aumenta el tiempo de procesamiento.
A32: 19.854153 | B32: =IF([2]Datos!B31="Estructurados",1,0) -> 1 | C32: 4 | D32: 17 | E32: 2 | F32: 15.62672 | H32: X2 | I32: Tipo de Datos: ESTRUCTURADOS=1, NO ESTRUCTURADOS=0 | N32: Los datos no estructurados suelen requerir mayor procesamiento por lo que afecta la variable dependiente(En este caso el tiempo de procesamiento).
A33: 12.699147 | B33: =IF([2]Datos!B32="Estructurados",1,0) -> 0 | C33: 5 | D33: 9 | E33: 5 | F33: 15.181406 | H33: X3 | I33: Calidad de Datos | N33: Una mejor calidad reduce errores y tareas de limpieza, favoreciendo un procesamiento más eficiente.
A34: 13.926139 | B34: =IF([2]Datos!B33="Estructurados",1,0) -> 1 | C34: 3 | D34: 19 | E34: 1 | F34: 10.242997 | H34: X4 | I34: Experiencia del Equipo (Años) | N34: Equipos con mayor experiencia pueden optimizar procesos, resolver incidencias con mayor rapidez y disminuir el tiempo de procesamiento.
A35: 17.993251 | B35: =IF([2]Datos!B34="Estructurados",1,0) -> 1 | C35: 2 | D35: 14 | E35: 2 | F35: 11.512925 | H35: X5 | I35: Nivel de Integración | N35: Un mayor nivel de integración entre los sistemas facilita el flujo de información y puede reducir retrasos durante el procesamiento.
A36: 20.471145 | B36: =IF([2]Datos!B35="Estructurados",1,0) -> 0 | C36: 4 | D36: 8 | E36: 4 | F36: 16.758651 | H36: Y | I36: Tiempo de Procesamiento (Horas) | N36: Es la variable que se desea investigar y predecir sus cambios.
A37: 10.411272 | B37: =IF([2]Datos!B36="Estructurados",1,0) -> 1 | C37: 4 | D37: 9 | E37: 4 | F37: 13.651707
A38: 17.389578 | B38: =IF([2]Datos!B37="Estructurados",1,0) -> 1 | C38: 4 | D38: 11 | E38: 3 | F38: 15.315752
A39: 18.104432 | B39: =IF([2]Datos!B38="Estructurados",1,0) -> 0 | C39: 2 | D39: 1 | E39: 3 | F39: 16.972522
A40: 14.020165 | B40: =IF([2]Datos!B39="Estructurados",1,0) -> 1 | C40: 4 | D40: 14 | E40: 4 | F40: 14.588141
...

Sheet 7. Coef. Determinación R2
A1: PUNTO 7 — INTERPRETACIÓN DEL COEFICIENTE DE DETERMINACIÓN R²
A3: Valor | B3: Resultado | C3: Interpretación
A4: R^2 ajustado | B4: 0.34453358 | C4: 7. El modelo explica el 34.45% de la variabilidad del tiempo de procesamiento, aún existe un 65.55% que no es explicado por las variables analizadas. Esto sugiere que pueden existir otros factores que también influyen en el tiempo de procesamiento.
A6: Observación: El resultado R² presentado aquí fue calculado en la hoja anterior solo se coloco aquí para llevar un mejor orden.

Sheet 8. Prediccion Puntual
A1: X | B1: Y | D1: PUNTO 8 — PREDICCIÓN PUNTUAL DEL TIEMPO DE PROCESAMIENTO PARA 20 GB
A2: Tamaño de DB (GB) | B2: Tiempo de Procesamiento (Horas) | L2: Resumen
A3: 18.248357 | B3: 12.650402
A4: 9.9308678 | B4: 7.846512 | E4: Variable a predecir | F4: Resultado | L4: Estadísticas de la regresión
A5: 16.323844 | B5: 18.293437 | E5: 8. X=20 GB | F5: =_xlfn.FORECAST.LINEAR(20,B3:B402,A3:A402) -> 15.109084 | K5: Correlación | L5: Coeficiente de correlación múltiple | M5: 0.3881193
A6: 19.761515 | B6: 16.354214 | L6: Coeficiente de determinación R^2 | M6: 0.15063659
A7: 10.882923 | B7: 12.844001 | L7: R^2 ajustado | M7: 0.14850252
A8: 12.882932 | B8: 12.094613 | L8: Error típico | M8: 2.876712
A9: 14.789606 | B9: 11.389639 | L9: Observaciones | M9: 400
A10: 16.383717 | B10: 9.9412842
A11: 11.765263 | B11: 17.777648 | L11: ANÁLISIS DE VARIANZA
A12: 14.27128 | B12: 17.904703 | M12: Grados de libertad | N12: Suma de cuadrados | O12: Promedio de los cuadrados | P12: F | Q12: Valor crítico de F
A13: 10.768291 | B13: 11.197855 | L13: Regresión | M13: 1 | N13: 584.1344 | O13: 584.1344 | P13: 70.586235 | Q13: 7.8787107e-16
A14: 15.767135 | B14: 13.224495 | K14: SCE | L14: Residuos | M14: 398 | N14: 3293.6378 | O14: 8.275472
A15: 16.120981 | B15: 11.319783 | K15: SCT | L15: Total | M15: 399 | N15: 3877.7722
A16: 12.04336 | B16: 16.053875
A17: 16.137541 | B17: 14.691368 | M17: Coeficientes | N17: Error típico | O17: Estadístico t | P17: Probabilidad | Q17: Inferior 95% | R17: Superior 95% | S17: Inferior 95.0% | T17: Superior 95.0%
A18: 9.7188562 | B18: 14.585084 | K18: Intercepto | L18: Intercepción | M18: 9.2821161 | N18: 0.53505334 | O18: 17.34802 | P18: 1.3024528e-50 | Q18: 8.2302321 | R18: 10.334 | S18: 8.2302321 | T18: 10.334
A19: 11.493584 | B19: 9.6594152 | K19: Pendiente | L19: Tamaño de DB (GB) | M19: 0.29134837 | N19: 0.034677884 | O19: 8.4015614 | P19: 7.8787107e-16 | Q19: 0.22317365 | R19: 0.35952309 | S19: 0.22317365 | T19: 0.35952309
A20: 13.157124 | B20: 14.24281
A21: 14.545988 | B21: 9.2541406 | K21: t Crítica | L21: =TINV(0.05,3) -> 3.1824463
A22: 8.2938481 | B22: 8.2039122
A23: 6.7328244 | B23: 14.952776
A24: 13.887112 | B24: 12.452029
A25: 19.033764 | B25: 11.223453
A26: 11.287626 | B26: 15.359404
A27: 9.7278086 | B27: 13.388666
A28: 18.055461 | B28: 12.905975
A29: 16.424503 | B29: 3.0225315
A30: 18.187849 | B30: 11.704678
A31: 12.699681 | B31: 16.054967
A32: 19.854153 | B32: 15.62672
A33: 12.699147 | B33: 15.181406
... A402: 20.618908 | B402: 11.988908

Sheet 9. Prob. No Estructurados
A1: PUNTO 9 — PROBABILIDAD DE QUE EL TIEMPO DE PROCESAMIENTO SUPERE LAS 8 HORAS EN DATOS NO ESTRUCTURADOS
C3: 9. Tipo de Datos No Estructurados
C4: Total | D4: =COUNTIF(Datos!B2:B401,"No Estructurados") -> 198
C5: Tiempo >8 | D5: =COUNTIFS(Datos!B2:B401,"No Estructurados",Datos!D2:D401,">8") -> 192
C6: Probabilidad | D6: =D5/D4 -> 0.96969697

Sheet 10. Prob Condicional
A1: PUNTO 10 — PROBABILIDAD CONDICIONAL
B3: 10 .Nivel de Integración
B4: Tiempo de procesamiento <8 | C4: =COUNTIF(Datos!D2:D401,"<8") -> 15
B5: Nivel de Integración 4 o 5 | C5: =COUNTIFS(Datos!D2:D401,"<8",Datos!G2:G401,4)+COUNTIFS(Datos!D2:D401,"<8",Datos!G2:G401,5) -> 2
B6: Probabilidad | C6: =(COUNTIFS(Datos!D2:D401,"<8",Datos!G2:G401,4)+COUNTIFS(Datos!D2:D401,"<8",Datos!G2:G401,5))/COUNTIF(Datos!D2:D401,"<8") -> 0.13333333

Sheet 11. Teorema Bayes
A1: Pregunta 11. Teorema de bayes | I1: Tiempo < 8h | J1: Calidad >=4
A2: n(calidad>=4) | B2: =SUM(J2:J401) -> 262 | I2: =IF(Datos!D2<8,1,0) -> 0 | J2: =IF(Datos!E2>=4,1,0) -> 0
A3: P(calidad>=4) | B3: =B2/400 -> 0.655 | I3: =IF(Datos!D3<8,1,0) -> 1 | J3: =IF(Datos!E3>=4,1,0) -> 1
I4: =IF(Datos!D4<8,1,0) -> 0 | J4: =IF(Datos!E4>=4,1,0) -> 1
A5: n(tiempo>8h) | B5: =SUM(I2:I401) -> 15 | I5: =IF(Datos!D5<8,1,0) -> 0 | J5: =IF(Datos!E5>=4,1,0) -> 1
A6: P(tiempo>8h) | B6: =B5/400 -> 0.0375 | I6: =IF(Datos!D6<8,1,0) -> 0 | J6: =IF(Datos!E6>=4,1,0) -> 1
I7: =IF(Datos!D7<8,1,0) -> 0 | J7: =IF(Datos!E7>=4,1,0) -> 0
A8: n(Tiempo <8 | calidad>=4) | B8: =SUMPRODUCT(J2:J401,I2:I401) -> 15 | I8: =IF(Datos!D8<8,1,0) -> 0 | J8: =IF(Datos!E8>=4,1,0) -> 0
A9: P(Tiempo <8 | calidad>=4) | B9: =B8/B2 -> 0.057251908 | I9: =IF(Datos!D9<8,1,0) -> 0 | J9: =IF(Datos!E9>=4,1,0) -> 1
A10: n(calidad>=4 | Tiempo <8) Bayes = M9*M3/M6 | B10: =B9*B3/B6 -> 1 | I10: =IF(Datos!D10<8,1,0) -> 0 | J10: =IF(Datos!E10>=4,1,0) -> 1
A11: Verificación directa: P = n(intersección)/n(Tiempo<8h) | B11: =B8/B5 -> 1 | I11: =IF(Datos!D11<8,1,0) -> 0 | J11: =IF(Datos!E11>=4,1,0) -> 0
I12: =IF(Datos!D12<8,1,0) -> 0 | J12: =IF(Datos!E12>=4,1,0) -> 1
A13: n(total) | B13: 400 | I13: =IF(Datos!D13<8,1,0) -> 0 | J13: =IF(Datos!E13>=4,1,0) -> 1
I14: =IF(Datos!D14<8,1,0) -> 0 | J14: =IF(Datos!E14>=4,1,0) -> 1
I15: =IF(Datos!D15<8,1,0) -> 0 | J15: =IF(Datos!E15>=4,1,0) -> 1
I16: =IF(Datos!D16<8,1,0) -> 0 | J16: =IF(Datos!E16>=4,1,0) -> 1
I17: =IF(Datos!D17<8,1,0) -> 0 | J17: =IF(Datos!E17>=4,1,0) -> 1
I18: =IF(Datos!D18<8,1,0) -> 0 | J18: =IF(Datos!E18>=4,1,0) -> 1
I19: =IF(Datos!D19<8,1,0) -> 0 | J19: =IF(Datos!E19>=4,1,0) -> 1
I20: =IF(Datos!D20<8,1,0) -> 0 | J20: =IF(Datos!E20>=4,1,0) -> 1
I21: =IF(Datos!D21<8,1,0) -> 0 | J21: =IF(Datos!E21>=4,1,0) -> 1
I22: =IF(Datos!D22<8,1,0) -> 0 | J22: =IF(Datos!E22>=4,1,0) -> 0
I23: =IF(Datos!D23<8,1,0) -> 0 | J23: =IF(Datos!E23>=4,1,0) -> 1
I24: =IF(Datos!D24<8,1,0) -> 0 | J24: =IF(Datos!E24>=4,1,0) -> 1
I25: =IF(Datos!D25<8,1,0) -> 0 | J25: =IF(Datos!E25>=4,1,0) -> 0
... I401: =IF(Datos!D401<8,1,0) -> 0 | J401: =IF(Datos!E401>=4,1,0) -> 1

Sheet 12. Independencia Eventos
A1: Pregunta 12. independencia de no Estructurados y Tiempo>8h
A2: n(No estructurados) | B2: =COUNTIF(Datos!B2:B401,"No estructurados") -> 198
A3: P(No estructurados) | B3: =B2/400 -> 0.495
A5: n(Tiempo>8h) | B5: =COUNTIF(Datos!D2:D401,">8") -> 385
A6: P(Tiempo>8h) | B6: =B5/400 -> 0.9625
A8: n(No estructurados y tiempo>8h) | B8: =COUNTIFS(Datos!B2:B401,"No Estructurados",Datos!D2:D401,">8") -> 192
A9: P(No estructurados ∩ tiempo>8h) observada | B9: =B8/400 -> 0.48
A10: P(No Estr)×P(Tiempo>8h) [si fueran independientes] | B10: =B3*B6 -> 0.4764375
A11: Diferencia (observada - esperada bajo independencia) | B11: =B9-B10 -> 0.0035625
A12: P(Tiempo>8h | no estructurados) | B12: =B8/B2 -> 0.96969697

Sheet 13. Benchmark Estandar
A1: Pregunta 13 - Comparación con estándares de la industria
A2: Tiempo prom. de procesamiento (Datatech) | D2: =AVERAGE(Datos!D2:D401) -> 13.611924
A3: % de cumplimiento del SLA interno | D3: =COUNTIF(Datos!D2:D401,"<8")/400 -> 0.0375
A4: Tiempo promedio esperado según estándar | D4: 13 h
A5: % de cumplimiento típico de SLA en la industria | D5: 95%-99%
A6: Fuente | D6: IBM, "Types of SLA Metrics", 2025
A7: Datatech es competitiva? | D7: No, cumplimiento muy por debajo del estándar

Sheet 14. SLA Cliente 3.5hrs
A1: Pregunta 14 - SLA cliente: Tiempo ≤ 3.5 horas
A2: n(Tiempo>3.5h) [incumple SLA cliente] | B2: =COUNTIF(Datos!D2:D401,">3.5") -> 398
A3: Proporción que incumple (>3.5h) | B3: =B2/400 -> 0.995
A4: n(Tiempo<=3.5h) [cumple SLA cliente] | B4: =COUNTIF(Datos!D2:D401,"<=3.5") -> 2
A5: Proporción que cumple (<=3.5h) | B5: =B4/400 -> 0.005
A6: Tiempo promedio de procesamiento (h) | B6: =AVERAGE(Datos!D2:D401) -> 13.611924
A7: Tiempo mínimo observado (h) | B7: =MIN(Datos!D2:D401) -> 3.0052546

Sheet 15. Tablas Contingencia
A1: Pregunta 15 - Tabla de contingencia: Tipo de Datos x Nivel de Integración
A3: 1- Tabla de frecuencias conjuntas
B4: 1 | C4: 2 | D4: 3 | E4: 4 | F4: 5 | G4: Total
A5: Estructurados | B5: =COUNTIFS(Datos!$B$2:$B$401,$A5,Datos!$G$2:$G$401,B$4) -> 50 | C5: =COUNTIFS(Datos!$B$2:$B$401,$A5,Datos!$G$2:$G$401,C$4) -> 36 | D5: =COUNTIFS(Datos!$B$2:$B$401,$A5,Datos!$G$2:$G$401,D$4) -> 50 | E5: =COUNTIFS(Datos!$B$2:$B$401,$A5,Datos!$G$2:$G$401,E$4) -> 24 | F5: =COUNTIFS(Datos!$B$2:$B$401,$A5,Datos!$G$2:$G$401,F$4) -> 42 | G5: =SUM(B5:F5) -> 202
A6: No Estructurados | B6: =COUNTIFS(Datos!$B$2:$B$401,$A6,Datos!$G$2:$G$401,B$4) -> 38 | C6: =COUNTIFS(Datos!$B$2:$B$401,$A6,Datos!$G$2:$G$401,C$4) -> 48 | D6: =COUNTIFS(Datos!$B$2:$B$401,$A6,Datos!$G$2:$G$401,D$4) -> 30 | E6: =COUNTIFS(Datos!$B$2:$B$401,$A6,Datos!$G$2:$G$401,E$4) -> 38 | F6: =COUNTIFS(Datos!$B$2:$B$401,$A6,Datos!$G$2:$G$401,F$4) -> 44 | G6: =SUM(B6:F6) -> 198
A7: Total | B7: =SUM(B5:B6) -> 88 | C7: =SUM(C5:C6) -> 84 | D7: =SUM(D5:D6) -> 80 | E7: =SUM(E5:E6) -> 62 | F7: =SUM(F5:F6) -> 86 | G7: =SUM(B7:F7) -> 400
A10: 2- Probabilidades conjuntas y marginales
B11: 1 | C11: 2 | D11: 3 | E11: 4 | F11: 5 | G11: Marginal tipo
A12: Estructurados | B12: =B5/400 -> 0.125 | C12: =C5/400 -> 0.09 | D12: =D5/400 -> 0.125 | E12: =E5/400 -> 0.06 | F12: =F5/400 -> 0.105 | G12: =G5/400 -> 0.505
A13: No Estructurados | B13: =B6/400 -> 0.095 | C13: =C6/400 -> 0.12 | D13: =D6/400 -> 0.075 | E13: =E6/400 -> 0.095 | F13: =F6/400 -> 0.11 | G13: =G6/400 -> 0.495
A14: Marginal Integración | B14: =B7/400 -> 0.22 | C14: =C7/400 -> 0.21 | D14: =D7/400 -> 0.2 | E14: =E7/400 -> 0.155 | F14: =F7/400 -> 0.215 | G14: =G7/400 -> 1
A17: 3- Frecuencia de incumplimiento del SLA
B18: 1 | C18: 2 | D18: 3 | E18: 4 | F18: 5
A19: Estructurados | B19: =COUNTIFS(Datos!$B$2:$B$401,$A19,Datos!$G$2:$G$401,B$18,Datos!$D$2:$D$401,">8") -> 43 | C19: =COUNTIFS(Datos!$B$2:$B$401,$A19,Datos!$G$2:$G$401,C$18,Datos!$D$2:$D$401,">8") -> 35 | D19: =COUNTIFS(Datos!$B$2:$B$401,$A19,Datos!$G$2:$G$401,D$18,Datos!$D$2:$D$401,">8") -> 49 | E19: =COUNTIFS(Datos!$B$2:$B$401,$A19,Datos!$G$2:$G$401,E$18,Datos!$D$2:$D$401,">8") -> 24 | F19: =COUNTIFS(Datos!$B$2:$B$401,$A19,Datos!$G$2:$G$401,F$18,Datos!$D$2:$D$401,">8") -> 42
A20: No Estructurados | B20: =COUNTIFS(Datos!$B$2:$B$401,$A20,Datos!$G$2:$G$401,B$18,Datos!$D$2:$D$401,">8") -> 36 | C20: =COUNTIFS(Datos!$B$2:$B$401,$A20,Datos!$G$2:$G$401,C$18,Datos!$D$2:$D$401,">8") -> 46 | D20: =COUNTIFS(Datos!$B$2:$B$401,$A20,Datos!$G$2:$G$401,D$18,Datos!$D$2:$D$401,">8") -> 30 | E20: =COUNTIFS(Datos!$B$2:$B$401,$A20,Datos!$G$2:$G$401,E$18,Datos!$D$2:$D$401,">8") -> 36 | F20: =COUNTIFS(Datos!$B$2:$B$401,$A20,Datos!$G$2:$G$401,F$18,Datos!$D$2:$D$401,">8") -> 44
A21: Combinación con mayor incumplimiento: | B21: ="Estructurados / Nivel 3 (n = "&D19&" registros que incumplen SLA)" -> Estructurados / Nivel 3 (n = 49 registros que incumplen SLA)
